Workbook

Sheet Summary
B1: ExerciseMenu: GIF purchase and placement plan
B2: Built from all 115 posts in exercisemenu.com/post-sitemap.xml, scanned 17 Oct 2026.
B4: Gym Visual price per GIF (1–9 in cart) | C4: 3.6 | D4: Source: gymvisual.com/content/6-price-rules (table was hard to read; confirm at checkout).
B5: Gym Visual price per GIF (10+ in cart) | C5: 0.9 | D5: Same source. Change these yellow cells if checkout shows a different price.
B6: Cart size where the lower price starts | C6: 10 | D6: Same source.
B8: Batch (buy in this order) | C8: GIFs | D8: Cost ($)
B9: 1. Replaces a WRONG image | C9: =COUNTIF('Buy List'!$B$2:$B$91,B9) -> 10 | D9: =SUMIF('Buy List'!$B$2:$B$91,B9,'Buy List'!$H$2:$H$91) -> 9
B10: 2. Used on 2+ pages | C10: =COUNTIF('Buy List'!$B$2:$B$91,B10) -> 8 | D10: =SUMIF('Buy List'!$B$2:$B$91,B10,'Buy List'!$H$2:$H$91) -> 7.2
B11: 3. Finish Beginners + Ab articles | C11: =COUNTIF('Buy List'!$B$2:$B$91,B11) -> 8 | D11: =SUMIF('Buy List'!$B$2:$B$91,B11,'Buy List'!$H$2:$H$91) -> 7.2
B12: 4. Rest of medicine ball cluster | C12: =COUNTIF('Buy List'!$B$2:$B$91,B12) -> 40 | D12: =SUMIF('Buy List'!$B$2:$B$91,B12,'Buy List'!$H$2:$H$91) -> 36
B13: 5. Squat & deadlift guides | C13: =COUNTIF('Buy List'!$B$2:$B$91,B13) -> 14 | D13: =SUMIF('Buy List'!$B$2:$B$91,B13,'Buy List'!$H$2:$H$91) -> 12.6
B14: 6. Cable chest & dumbbell guide | C14: =COUNTIF('Buy List'!$B$2:$B$91,B14) -> 10 | D14: =SUMIF('Buy List'!$B$2:$B$91,B14,'Buy List'!$H$2:$H$91) -> 9
B15: Total | C15: =SUM(C9:C14) -> 90 | D15: =SUM(D9:D14) -> 81
B16: Bought so far | C16: =COUNTIF('Buy List'!$I$2:$I$91,"Y") -> 0
B18: Placements by action | C18: Images
B19: Replace image with GIF | C19: =COUNTIF(Placements!$G$2:$G$155,B19) -> 16
B20: Add GIF beside image | C20: =COUNTIF(Placements!$G$2:$G$155,B20) -> 75
B21: Add GIF (no image now) | C21: =COUNTIF(Placements!$G$2:$G$155,B21) -> 15
B22: Keep image | C22: =COUNTIF(Placements!$G$2:$G$155,B22) -> 38
B23: Already a GIF (reuse) | C23: =COUNTIF(Placements!$G$2:$G$155,B23) -> 9
B24: Fix or regenerate image (no GIF) | C24: =COUNTIF(Placements!$G$2:$G$155,B24) -> 1
B26: Image check | C26: Images
B27: OK | C27: =COUNTIF(Placements!$K$2:$K$155,B27) -> 99
B28: Minor issue | C28: =COUNTIF(Placements!$K$2:$K$155,B28) -> 26
B29: WRONG | C29: =COUNTIF(Placements!$K$2:$K$155,B29) -> 11
B31: Notes
B32: How to use | D32: 1) Buy from the Buy List top to bottom; one GIF serves every article in its row. 2) Mark Bought = Y (yellow column). 3) Use the Placements sheet to put each GIF in the right article, section and position.
B33: Yellow cells | D33: The only cells to edit: prices on this sheet and the Bought column on the Buy List. Everything else is calculated.
B34: Gym Visual IDs | D34: Only 6 IDs were found (gymvisual.com is blocked in this session). For the rest, search the exercise name on gymvisual.com and type the ID in.
B35: Already GIFs | D35: front-squat-vs-back-squat and high-bar-vs-low-bar-squat already use animated GIFs with good form, and the beginners article's slam, overhead press and Russian twist are video GIFs of 7-8 MB each. No purchase needed: convert those three to MP4.
B36: Partner & kids pages | D36: Kept on purpose: Gym Visual animates one person, and the kids page shows a child. Replace only if an image shows wrong form.
B37: Image check | D37: All images were viewed one by one (17 Oct 2026). WRONG = shows the wrong exercise, impossible position, or garbled text: fix these first. Minor = text/label slips; fix when editing the article.
B38: Infographics kept | D38: Most medicine ball images are branded ExerciseMenu infographics with cues and do/don't panels, which competitors don't have. They are kept; the GIF is added above them.
B39: First purchase list | D39: Backward throw, rotational throw and plain crunch from the first 12-GIF list are on no page, so they are not here.

Sheet Buy List
A1: Buy # | B1: Batch | C1: Exercise (GIF to buy) | D1: Gym Visual ID | E1: Gym Visual link / title to search | F1: Placements on site | G1: Articles it goes in | H1: Price per GIF ($) | I1: Bought? (Y/N) | J1: Notes
A2: 1 | B2: 1. Replaces a WRONG image | C2: Dumbbell Sumo Squat | D2: not found yet | E2: Search: Dumbbell Sumo Squat | F2: =COUNTIFS(Placements!$F:$F,$C2,Placements!$I:$I,"Yes") -> 2 | G2: /dumbbell-sumo-squat/, /types-of-squats/ | H2: =IF(COUNTA($C$2:$C$91)>=Summary!$C$6,Summary!$C$5,Summary!$C$4) -> 0.9
A3: 2 | B3: 1. Replaces a WRONG image | C3: Medicine Ball Forward Lunge with Twist | D3: not found yet | E3: Search: Medicine Ball Forward Lunge with Twist | F3: =COUNTIFS(Placements!$F:$F,$C3,Placements!$I:$I,"Yes") -> 2 | G3: /exercises-with-a-medicine-ball-for-beginners/, /10-medicine-ball-exercises-for-legs/ | H3: =IF(COUNTA($C$2:$C$91)>=Summary!$C$6,Summary!$C$5,Summary!$C$4) -> 0.9
A4: 3 | B4: 1. Replaces a WRONG image | C4: Medicine Ball Glute Bridge | D4: not found yet | E4: Search: Medicine Ball Glute Bridge | F4: =COUNTIFS(Placements!$F:$F,$C4,Placements!$I:$I,"Yes") -> 2 | G4: /exercises-with-a-medicine-ball-for-beginners/, /10-medicine-ball-exercises-for-legs/ | H4: =IF(COUNTA($C$2:$C$91)>=Summary!$C$6,Summary!$C$5,Summary!$C$4) -> 0.9
A5: 4 | B5: 1. Replaces a WRONG image | C5: Medicine Ball Dead Bug | D5: 10176 | E5: https://gymvisual.com/animated-gifs/10176-dead-bug-with-medicine-ball-male.html | F5: =COUNTIFS(Placements!$F:$F,$C5,Placements!$I:$I,"Yes") -> 2 | G5: /medicine-ball-ab-exercises/, /medicine-ball-exercises-for-lower-abs/ | H5: =IF(COUNTA($C$2:$C$91)>=Summary!$C$6,Summary!$C$5,Summary!$C$4) -> 0.9
A6: 5 | B6: 1. Replaces a WRONG image | C6: Medicine Ball Leg Raise | D6: 13026 | E6: https://gymvisual.com/animated-gifs/13026-medicine-ball-lying-leg-raise.html | F6: =COUNTIFS(Placements!$F:$F,$C6,Placements!$I:$I,"Yes") -> 2 | G6: /medicine-ball-ab-exercises/, /medicine-ball-exercises-for-lower-abs/ | H6: =IF(COUNTA($C$2:$C$91)>=Summary!$C$6,Summary!$C$5,Summary!$C$4) -> 0.9
A7: 6 | B7: 1. Replaces a WRONG image | C7: Medicine Ball Lying Triceps Press | D7: not found yet | E7: Search: Medicine Ball Lying Triceps Press | F7: =COUNTIFS(Placements!$F:$F,$C7,Placements!$I:$I,"Yes") -> 1 | G7: /10-medicine-ball-exercises-for-arms/ | H7: =IF(COUNTA($C$2:$C$91)>=Summary!$C$6,Summary!$C$5,Summary!$C$4) -> 0.9
A8: 7 | B8: 1. Replaces a WRONG image | C8: Medicine Ball Single-Arm Shoulder Press | D8: not found yet | E8: Search: Medicine Ball Single-Arm Shoulder Press | F8: =COUNTIFS(Placements!$F:$F,$C8,Placements!$I:$I,"Yes") -> 1 | G8: /10-medicine-ball-exercises-for-arms/ | H8: =IF(COUNTA($C$2:$C$91)>=Summary!$C$6,Summary!$C$5,Summary!$C$4) -> 0.9
A9: 8 | B9: 1. Replaces a WRONG image | C9: Cable Crossover | D9: not found yet | E9: Search: Cable Crossover | F9: =COUNTIFS(Placements!$F:$F,$C9,Placements!$I:$I,"Yes") -> 1 | G9: /cable-chest-exercises-10-best-moves/ | H9: =IF(COUNTA($C$2:$C$91)>=Summary!$C$6,Summary!$C$5,Summary!$C$4) -> 0.9
A10: 9 | B10: 1. Replaces a WRONG image | C10: Dumbbell Shoulder Press | D10: not found yet | E10: Search: Dumbbell Shoulder Press | F10: =COUNTIFS(Placements!$F:$F,$C10,Placements!$I:$I,"Yes") -> 1 | G10: /how-to-train-deltoids-and-biceps-with-dumbbells/ | H10: =IF(COUNTA($C$2:$C$91)>=Summary!$C$6,Summary!$C$5,Summary!$C$4) -> 0.9
A11: 10 | B11: 1. Replaces a WRONG image | C11: Sumo Deadlift | D11: not found yet | E11: Search: Sumo Deadlift | F11: =COUNTIFS(Placements!$F:$F,$C11,Placements!$I:$I,"Yes") -> 1 | G11: /sumo-vs-conventional-deadlift/ | H11: =IF(COUNTA($C$2:$C$91)>=Summary!$C$6,Summary!$C$5,Summary!$C$4) -> 0.9
A12: 11 | B12: 2. Used on 2+ pages | C12: Medicine Ball Slam | D12: 3125 | E12: https://gymvisual.com/animated-gifs/3125-medicine-ball-overhead-slam.html | F12: =COUNTIFS(Placements!$F:$F,$C12,Placements!$I:$I,"Yes") -> 3 | G12: /10-medicine-ball-exercises-for-back/, /10-medicine-ball-exercises-for-arms/, /medicine-ball-exercises-for-shoulders/ | H12: =IF(COUNTA($C$2:$C$91)>=Summary!$C$6,Summary!$C$5,Summary!$C$4) -> 0.9
A13: 12 | B13: 2. Used on 2+ pages | C13: Medicine Ball Push-Up (hands on ball) | D13: not found yet | E13: Search: Medicine Ball Close Grip Push Up | F13: =COUNTIFS(Placements!$F:$F,$C13,Placements!$I:$I,"Yes") -> 3 | G13: /exercises-with-a-medicine-ball-for-beginners/, /10-medicine-ball-chest-exercises/, /medicine-ball-exercises-for-shoulders/ | H13: =IF(COUNTA($C$2:$C$91)>=Summary!$C$6,Summary!$C$5,Summary!$C$4) -> 0.9
... A91: 90 | B91: 6. Cable chest & dumbbell guide | C91: Dumbbell Lateral Raise | D91: not found yet | E91: Search: Dumbbell Lateral Raise | F91: =COUNTIFS(Placements!$F:$F,$C91,Placements!$I:$I,"Yes") -> 1 | G91: /how-to-train-deltoids-and-biceps-with-dumbbells/ | H91: =IF(COUNTA($C$2:$C$91)>=Summary!$C$6,Summary!$C$5,Summary!$C$4) -> 0.9

Sheet Placements
A1: # | B1: Article URL | C1: Section (heading on the page) | D1: Position | E1: Current image file | F1: Exercise (GIF) | G1: Action | H1: Notes | I1: Needs a purchased GIF? | J1: Buy # | K1: Image check | L1: What the check found
A2: 1 | B2: https://exercisemenu.com/exercises-with-a-medicine-ball-for-beginners/ | C2: 1. Medicine Ball Slam | D2: Image 1 on page | E2: Cinematic_frontangle_shot_welllit_indoor_g.gif | F2: Medicine Ball Slam | G2: Already a GIF (reuse) | H2: Already a video GIF (7-8 MB). Convert to MP4 instead of buying. | I2: No | J2: =IF($I2="Yes",IFERROR(INDEX('Buy List'!$A$2:$A$91,MATCH($F2,'Buy List'!$C$2:$C$91,0)),"-"),"-") -> - | K2: OK | L2: Already an animated GIF from video (128 frames). Form is good. 8 MB: convert to MP4.
A3: 2 | B3: https://exercisemenu.com/exercises-with-a-medicine-ball-for-beginners/ | C3: 2. Medicine Ball Overhead Press | D3: Image 2 on page | E3: Medicine-Ball-Overhead-Press.gif | F3: Medicine Ball Overhead Press | G3: Already a GIF (reuse) | H3: Already a video GIF (7-8 MB). Convert to MP4 instead of buying. | I3: No | J3: =IF($I3="Yes",IFERROR(INDEX('Buy List'!$A$2:$A$91,MATCH($F3,'Buy List'!$C$2:$C$91,0)),"-"),"-") -> - | K3: OK | L3: Already an animated GIF from video (128 frames). Form is good. 7 MB: convert to MP4.
A4: 3 | B4: https://exercisemenu.com/exercises-with-a-medicine-ball-for-beginners/ | C4: 3. Medicine Ball Push-Up | D4: Image 3 on page | E4: medicine-ball-pushup-two-panel-683x1024.webp | F4: Medicine Ball Push-Up (hands on ball) | G4: Replace image with GIF | I4: Yes | J4: =IF($I4="Yes",IFERROR(INDEX('Buy List'!$A$2:$A$91,MATCH($F4,'Buy List'!$C$2:$C$91,0)),"-"),"-") -> 12 | K4: OK | L4: Two-photo sequence, form fine.
A5: 4 | B5: https://exercisemenu.com/exercises-with-a-medicine-ball-for-beginners/ | C5: 4. Chest Pass Against a Wall | D5: Image 4 on page | E5: medicine-ball-wall-throw-two-panel-683x1024.webp | F5: Medicine Ball Chest Pass (wall) | G5: Replace image with GIF | I5: Yes | J5: =IF($I5="Yes",IFERROR(INDEX('Buy List'!$A$2:$A$91,MATCH($F5,'Buy List'!$C$2:$C$91,0)),"-"),"-") -> 16 | K5: OK | L5: Two-photo sequence, form fine (steps into the throw).
A6: 5 | B6: https://exercisemenu.com/exercises-with-a-medicine-ball-for-beginners/ | C6: 5. Russian twist | D6: Image 5 on page | E6: Medicine-ball-Russian-twist-exercise.gif | F6: Medicine Ball Russian Twist | G6: Already a GIF (reuse) | H6: Already a video GIF (7-8 MB). Convert to MP4 instead of buying. | I6: No | J6: =IF($I6="Yes",IFERROR(INDEX('Buy List'!$A$2:$A$91,MATCH($F6,'Buy List'!$C$2:$C$91,0)),"-"),"-") -> - | K6: Minor issue | L6: Already an animated GIF from video (128 frames, 7.6 MB). Torso barely turns; the arms do most of the twist. Convert to MP4.
A7: 6 | B7: https://exercisemenu.com/exercises-with-a-medicine-ball-for-beginners/ | C7: 6. Wood chop | D7: Image 6 on page | E7: medicine-ball-woodchop-correct-form-683x1024.webp | F7: Medicine Ball Wood Chop | G7: Replace image with GIF | I7: Yes | J7: =IF($I7="Yes",IFERROR(INDEX('Buy List'!$A$2:$A$91,MATCH($F7,'Buy List'!$C$2:$C$91,0)),"-"),"-") -> 17 | K7: OK | L7: Low-to-high chop path is correct.
A8: 7 | B8: https://exercisemenu.com/exercises-with-a-medicine-ball-for-beginners/ | C8: 7. Plank ball pass | D8: Image 7 on page | E8: medicine-ball-plank-roll-two-panel-683x1024.webp | F8: Medicine Ball Plank Pass | G8: Replace image with GIF | I8: Yes | J8: =IF($I8="Yes",IFERROR(INDEX('Buy List'!$A$2:$A$91,MATCH($F8,'Buy List'!$C$2:$C$91,0)),"-"),"-") -> 19 | K8: OK | L8: Hips level, form fine.
A9: 8 | B9: https://exercisemenu.com/exercises-with-a-medicine-ball-for-beginners/ | C9: 8. V-Up With Medicine Ball | D9: Image 8 on page | E9: medicine-ball-vup-two-panel-683x1024.webp | F9: Medicine Ball V-Up | G9: Replace image with GIF | I9: Yes | J9: =IF($I9="Yes",IFERROR(INDEX('Buy List'!$A$2:$A$91,MATCH($F9,'Buy List'!$C$2:$C$91,0)),"-"),"-") -> 13 | K9: OK | L9: Form fine.
A10: 9 | B10: https://exercisemenu.com/exercises-with-a-medicine-ball-for-beginners/ | C10: 9. Squat and press | D10: Image 9 on page | E10: squat-to-overhead-press-medicine-ball-683x1024.webp | F10: Medicine Ball Squat to Overhead Press | G10: Replace image with GIF | I10: Yes | J10: =IF($I10="Yes",IFERROR(INDEX('Buy List'!$A$2:$A$91,MATCH($F10,'Buy List'!$C$2:$C$91,0)),"-"),"-") -> 21 | K10: OK | L10: Form fine.
A11: 10 | B11: https://exercisemenu.com/exercises-with-a-medicine-ball-for-beginners/ | C11: 10. Forward lunge with twist | D11: Image 10 on page | E11: lunge-rotation-medicine-ball-two-panel-683x1024.webp | F11: Medicine Ball Forward Lunge with Twist | G11: Replace image with GIF | I11: Yes | J11: =IF($I11="Yes",IFERROR(INDEX('Buy List'!$A$2:$A$91,MATCH($F11,'Buy List'!$C$2:$C$91,0)),"-"),"-") -> 2 | K11: Minor issue | L11: Back knee rests on the floor (static kneel, not a lunge) and the ball moves with the arms more than the torso.
A12: 11 | B12: https://exercisemenu.com/exercises-with-a-medicine-ball-for-beginners/ | C12: 11. Medicine ball Romanian deadlift | D12: Image 11 on page | E12: Medicine-ball-Romanian-deadlift-683x1024.webp | F12: Medicine Ball Romanian Deadlift | G12: Replace image with GIF | I12: Yes | J12: =IF($I12="Yes",IFERROR(INDEX('Buy List'!$A$2:$A$91,MATCH($F12,'Buy List'!$C$2:$C$91,0)),"-"),"-") -> 20 | K12: Minor issue | L12: Knees almost locked; reads as a stiff-leg deadlift more than an RDL.
A13: 12 | B13: https://exercisemenu.com/exercises-with-a-medicine-ball-for-beginners/ | C13: 12. Glute bridge with ball squeeze | D13: Image 12 on page | E13: medicine-ball-glute-bridge-two-panel-683x1024.webp | F13: Medicine Ball Glute Bridge | G13: Replace image with GIF | H13: Ball squeezed between knees | I13: Yes | J13: =IF($I13="Yes",IFERROR(INDEX('Buy List'!$A$2:$A$91,MATCH($F13,'Buy List'!$C$2:$C$91,0)),"-"),"-") -> 3 | K13: WRONG | L13: Ball sits on top of the knees, but the heading and alt text say it is squeezed between the knees.
A14: 13 | B14: https://exercisemenu.com/medicine-ball-ab-exercises/ | C14: 1. Medicine Ball Sit-Up | D14: Image 1 on page | E14: Medicine-Ball-Sit-Up-1024x555.webp | F14: Medicine Ball Sit-Up | G14: Add GIF beside image | H14: Keep the branded infographic (cues, sets, do/don't) and add the GIF above it | I14: Yes | J14: =IF($I14="Yes",IFERROR(INDEX('Buy List'!$A$2:$A$91,MATCH($F14,'Buy List'!$C$2:$C$91,0)),"-"),"-") -> 25 | K14: OK | L14: Branded infographic with cues, sets and reps.
A15: 14 | B15: https://exercisemenu.com/medicine-ball-ab-exercises/ | C15: 2. Medicine Ball V-Up | D15: Image 2 on page | E15: medicine-ball-ab-v-up-1024x683.webp | F15: Medicine Ball V-Up | G15: Add GIF beside image | H15: Keep the branded infographic (cues, sets, do/don't) and add the GIF above it | I15: Yes | J15: =IF($I15="Yes",IFERROR(INDEX('Buy List'!$A$2:$A$91,MATCH($F15,'Buy List'!$C$2:$C$91,0)),"-"),"-") -> 13 | K15: OK | L15: Branded infographic, form fine.
A16: 15 | B16: https://exercisemenu.com/medicine-ball-ab-exercises/ | C16: 3. Table Top Crunch with Medicine Ball | D16: Image 3 on page | E16: medicine-ball-ab-table-top-crunch-1024x683.jpeg | F16: Medicine Ball Table Top Crunch | G16: Add GIF beside image | H16: Keep the branded infographic (cues, sets, do/don't) and add the GIF above it | I16: Yes | J16: =IF($I16="Yes",IFERROR(INDEX('Buy List'!$A$2:$A$91,MATCH($F16,'Buy List'!$C$2:$C$91,0)),"-"),"-") -> 26 | K16: Minor issue | L16: Alt text says the ball rests on the shins; image shows it held in the hands.
A17: 16 | B17: https://exercisemenu.com/medicine-ball-ab-exercises/ | C17: 4. Medicine Ball Leg Raise | D17: Image 4 on page | E17: medicine-ball-ab-leg-raise-1024x683.jpeg | F17: Medicine Ball Leg Raise | G17: Add GIF beside image | H17: Keep the branded infographic (cues, sets, do/don't) and add the GIF above it | I17: Yes | J17: =IF($I17="Yes",IFERROR(INDEX('Buy List'!$A$2:$A$91,MATCH($F17,'Buy List'!$C$2:$C$91,0)),"-"),"-") -> 5 | K17: OK | L17: Branded infographic, form fine.
A18: 17 | B18: https://exercisemenu.com/medicine-ball-ab-exercises/ | C18: 5. Medicine Ball Reverse Crunch | D18: Image 5 on page | E18: Medicine-Ball-Reverse-Crunch-1024x683.jpeg | F18: Medicine Ball Reverse Crunch | G18: Add GIF beside image | H18: Keep the branded infographic (cues, sets, do/don't) and add the GIF above it | I18: Yes | J18: =IF($I18="Yes",IFERROR(INDEX('Buy List'!$A$2:$A$91,MATCH($F18,'Buy List'!$C$2:$C$91,0)),"-"),"-") -> 18 | K18: Minor issue | L18: Image also contains a 'Medicine Ball Side Bend' panel, which is not one of the article's exercises.
A19: 18 | B19: https://exercisemenu.com/medicine-ball-ab-exercises/ | C19: 6. Medicine Ball Russian Twist | D19: Image 6 on page | E19: medicine-ball-ab-russian-twist-1024x683.webp | F19: Medicine Ball Russian Twist | G19: Add GIF beside image | H19: Keep the branded infographic (cues, sets, do/don't) and add the GIF above it | I19: Yes | J19: =IF($I19="Yes",IFERROR(INDEX('Buy List'!$A$2:$A$91,MATCH($F19,'Buy List'!$C$2:$C$91,0)),"-"),"-") -> 24 | K19: OK | L19: Branded infographic, form fine.
A20: 19 | B20: https://exercisemenu.com/medicine-ball-ab-exercises/ | C20: 7. Medicine Ball Wood Chop (Standing) | D20: Image 7 on page | E20: Medicine-Ball-Wood-Chop-1024x683.webp | F20: Medicine Ball Wood Chop | G20: Add GIF beside image | H20: Keep the branded infographic (cues, sets, do/don't) and add the GIF above it | I20: Yes | J20: =IF($I20="Yes",IFERROR(INDEX('Buy List'!$A$2:$A$91,MATCH($F20,'Buy List'!$C$2:$C$91,0)),"-"),"-") -> 17 | K20: Minor issue | L20: Different model and style from the rest of the article; chop path fine.
A21: 20 | B21: https://exercisemenu.com/medicine-ball-ab-exercises/ | C21: 8. Medicine Ball Plank | D21: Image 8 on page | E21: Medicine-Ball-Plank-1024x683.jpeg | F21: Medicine Ball Plank (hands on ball) | G21: Add GIF beside image | H21: Keep the branded infographic (cues, sets, do/don't) and add the GIF above it | I21: Yes | J21: =IF($I21="Yes",IFERROR(INDEX('Buy List'!$A$2:$A$91,MATCH($F21,'Buy List'!$C$2:$C$91,0)),"-"),"-") -> 22 | K21: OK | L21: Three identical panels; fine for a hold.
A22: 21 | B22: https://exercisemenu.com/medicine-ball-ab-exercises/ | C22: 9. Dead Bug with Medicine Ball Overhead | D22: Image 9 on page | E22: Dead-Bug-with-Medicine-Ball-Overhead-1024x683.jpeg | F22: Medicine Ball Dead Bug | G22: Replace image with GIF | H22: Article version holds the ball overhead | I22: Yes | J22: =IF($I22="Yes",IFERROR(INDEX('Buy List'!$A$2:$A$91,MATCH($F22,'Buy List'!$C$2:$C$91,0)),"-"),"-") -> 4 | K22: WRONG | L22: Text says lower 'your right arm (with the ball)' while the ball is held in both hands; image and instruction contradict each other.
A23: 22 | B23: https://exercisemenu.com/medicine-ball-ab-exercises/ | C23: 10. Standing Rotational Slam | D23: Under this heading | E23: (none) | F23: Medicine Ball Rotational Slam | G23: Add GIF (no image now) | H23: Section has no image yet | I23: Yes | J23: =IF($I23="Yes",IFERROR(INDEX('Buy List'!$A$2:$A$91,MATCH($F23,'Buy List'!$C$2:$C$91,0)),"-"),"-") -> 23 | K23: - | L23: No image to check
A24: 23 | B24: https://exercisemenu.com/medicine-ball-exercises-for-lower-abs/ | C24: 1. Medicine Ball Leg Raises | D24: Image 1 on page | E24: medicine-ball-leg-raises-step-by-step.webp-1024x683.webp | F24: Medicine Ball Leg Raise | G24: Replace image with GIF | I24: Yes | J24: =IF($I24="Yes",IFERROR(INDEX('Buy List'!$A$2:$A$91,MATCH($F24,'Buy List'!$C$2:$C$91,0)),"-"),"-") -> 5 | K24: WRONG | L24: Ball balances on top of the feet instead of being squeezed between them; it would fall in a real rep.
A25: 24 | B25: https://exercisemenu.com/medicine-ball-exercises-for-lower-abs/ | C25: 2. Medicine Ball Reverse Crunch | D25: Image 2 on page | E25: medicine-ball-reverse-crunch-step-by-step.webp-1024x683.webp | F25: Medicine Ball Reverse Crunch | G25: Add GIF beside image | H25: Keep the branded infographic (cues, sets, do/don't) and add the GIF above it | I25: Yes | J25: =IF($I25="Yes",IFERROR(INDEX('Buy List'!$A$2:$A$91,MATCH($F25,'Buy List'!$C$2:$C$91,0)),"-"),"-") -> 18 | K25: OK | L25: Clear, with lower-back insets.
A26: 25 | B26: https://exercisemenu.com/medicine-ball-exercises-for-lower-abs/ | C26: 3. Medicine Ball Flutter Kicks | D26: Image 3 on page | E26: medicine-ball-flutter-kicks-step-by-step.webp-1024x597.webp | F26: Medicine Ball Flutter Kicks | G26: Add GIF beside image | H26: Keep the branded infographic (cues, sets, do/don't) and add the GIF above it | I26: Yes | J26: =IF($I26="Yes",IFERROR(INDEX('Buy List'!$A$2:$A$91,MATCH($F26,'Buy List'!$C$2:$C$91,0)),"-"),"-") -> 54 | K26: OK | L26: Clear and detailed.
A27: 26 | B27: https://exercisemenu.com/medicine-ball-exercises-for-lower-abs/ | C27: 4. Medicine Ball V-Up | D27: Image 4 on page | E27: medicine-ball-v-up-step-by-step.webp-1024x683.webp | F27: Medicine Ball V-Up | G27: Add GIF beside image | H27: Keep the branded infographic (cues, sets, do/don't) and add the GIF above it | I27: Yes | J27: =IF($I27="Yes",IFERROR(INDEX('Buy List'!$A$2:$A$91,MATCH($F27,'Buy List'!$C$2:$C$91,0)),"-"),"-") -> 13 | K27: Minor issue | L27: Step 4 caption is garbled ('Lower both back down slowly').
A28: 27 | B28: https://exercisemenu.com/medicine-ball-exercises-for-lower-abs/ | C28: 5. Medicine Ball Dead Bug | D28: Image 5 on page | E28: how-to-do-medicine-ball-dead-bug.webp-1024x597.webp | F28: Medicine Ball Dead Bug | G28: Add GIF beside image | H28: Keep the branded infographic (cues, sets, do/don't) and add the GIF above it | I28: Yes | J28: =IF($I28="Yes",IFERROR(INDEX('Buy List'!$A$2:$A$91,MATCH($F28,'Buy List'!$C$2:$C$91,0)),"-"),"-") -> 4 | K28: OK | L28: Clear, opposite arm and leg correct.
A29: 28 | B29: https://exercisemenu.com/medicine-ball-exercises-for-lower-abs/ | C29: 6. Medicine Ball Hollow Hold | D29: Image 6 on page | E29: medicine-ball-hollow-hold-step-by-step.webp-1024x597.webp | F29: Medicine Ball Hollow Hold | G29: Add GIF beside image | H29: Keep the branded infographic (cues, sets, do/don't) and add the GIF above it | I29: Yes | J29: =IF($I29="Yes",IFERROR(INDEX('Buy List'!$A$2:$A$91,MATCH($F29,'Buy List'!$C$2:$C$91,0)),"-"),"-") -> 56 | K29: OK | L29: Clear.
A30: 29 | B30: https://exercisemenu.com/medicine-ball-exercises-for-lower-abs/ | C30: 7. Medicine Ball Knee Tuck to Leg Extension | D30: Image 7 on page | E30: medicine-ball-knee-tuck-to-leg-extension-step-by-step.webp-1024x597.webp | F30: Medicine Ball Knee Tuck to Leg Extension | G30: Add GIF beside image | H30: Keep the branded infographic (cues, sets, do/don't) and add the GIF above it | I30: Yes | J30: =IF($I30="Yes",IFERROR(INDEX('Buy List'!$A$2:$A$91,MATCH($F30,'Buy List'!$C$2:$C$91,0)),"-"),"-") -> 57 | K30: OK | L30: Clear.
A31: 30 | B31: https://exercisemenu.com/medicine-ball-exercises-for-lower-abs/ | C31: 8. Medicine Ball Pass (Hands to Feet) | D31: Image 8 on page | E31: medicine-ball-pass-hands-to-feet-step-by-step.webp-1024x597.webp | F31: Medicine Ball Hand-to-Feet Pass | G31: Add GIF beside image | H31: Keep the branded infographic (cues, sets, do/don't) and add the GIF above it | I31: Yes | J31: =IF($I31="Yes",IFERROR(INDEX('Buy List'!$A$2:$A$91,MATCH($F31,'Buy List'!$C$2:$C$91,0)),"-"),"-") -> 55 | K31: OK | L31: Clear.
A32: 31 | B32: https://exercisemenu.com/medicine-ball-exercises-for-lower-abs/ | C32: 9. Medicine Ball Plank with Knee Drive | D32: Image 9 on page | E32: medicine-ball-plank-with-knee-drive-step-by-step.webp-1024x597.webp | F32: Medicine Ball Plank with Knee Drive | G32: Add GIF beside image | H32: Keep the branded infographic (cues, sets, do/don't) and add the GIF above it | I32: Yes | J32: =IF($I32="Yes",IFERROR(INDEX('Buy List'!$A$2:$A$91,MATCH($F32,'Buy List'!$C$2:$C$91,0)),"-"),"-") -> 59 | K32: OK | L32: Clear.
A33: 32 | B33: https://exercisemenu.com/medicine-ball-exercises-for-lower-abs/ | C33: 10. Medicine Ball Overhead Crunch with Hip Raise | D33: Image 10 on page | E33: medicine-ball-overhead-crunch-with-hip-raise-step-by-step.webp-1024x597.webp | F33: Medicine Ball Overhead Crunch with Hip Raise | G33: Add GIF beside image | H33: Keep the branded infographic (cues, sets, do/don't) and add the GIF above it | I33: Yes | J33: =IF($I33="Yes",IFERROR(INDEX('Buy List'!$A$2:$A$91,MATCH($F33,'Buy List'!$C$2:$C$91,0)),"-"),"-") -> 58 | K33: OK | L33: Clear.
A34: 33 | B34: https://exercisemenu.com/10-medicine-ball-exercises-for-legs/ | C34: 1. Medicine Ball Squat | D34: Image 1 on page | E34: medicine-ball-squat-quads-glutes-1024x683.webp | F34: Medicine Ball Squat | G34: Add GIF beside image | H34: Keep the branded infographic (cues, sets, do/don't) and add the GIF above it | I34: Yes | J34: =IF($I34="Yes",IFERROR(INDEX('Buy List'!$A$2:$A$91,MATCH($F34,'Buy List'!$C$2:$C$91,0)),"-"),"-") -> 52 | K34: Minor issue | L34: Stance is shoulder-width in the start panel but very wide in the bottom panel.
A35: 34 | B35: https://exercisemenu.com/10-medicine-ball-exercises-for-legs/ | C35: 2. Medicine Ball Reverse Lunge | D35: Image 2 on page | E35: medicine-ball-reverse-lunge-hamstrings-glutes-female-1024x683.webp | F35: Medicine Ball Reverse Lunge | G35: Add GIF beside image | H35: Keep the branded infographic (cues, sets, do/don't) and add the GIF above it | I35: Yes | J35: =IF($I35="Yes",IFERROR(INDEX('Buy List'!$A$2:$A$91,MATCH($F35,'Buy List'!$C$2:$C$91,0)),"-"),"-") -> 49 | K35: OK | L35: Good: shin vertical, torso upright.
A36: 35 | B36: https://exercisemenu.com/10-medicine-ball-exercises-for-legs/ | C36: 3. Wall Ball | D36: Image 3 on page | E36: wall-ball-quads-glutes-power-1024x640.webp | F36: Wall Ball | G36: Add GIF beside image | H36: Keep the branded infographic (cues, sets, do/don't) and add the GIF above it | I36: Yes | J36: =IF($I36="Yes",IFERROR(INDEX('Buy List'!$A$2:$A$91,MATCH($F36,'Buy List'!$C$2:$C$91,0)),"-"),"-") -> 53 | K36: OK | L36: Good.
... A41: 40 | B41: https://exercisemenu.com/10-medicine-ball-exercises-for-legs/ | C41: 8. Overhead Walking Lunge | D41: Image 8 on page | E41: overhead-walking-lunge-quads-glutes-core-female-1024x683.webp | F41: Medicine Ball Overhead Walking Lunge | G41: Add GIF beside image | H41: Keep the branded infographic (cues, sets, do/don't) and add the GIF above it | I41: Yes | J41: =IF($I41="Yes",IFERROR(INDEX('Buy List'!$A$2:$A$91,MATCH($F41,'Buy List'!$C$2:$C$91,0)),"-"),"-") -> 48 | K41: OK | L41: Good, includes alignment and wrong example.
A42: 41 | B42: https://exercisemenu.com/10-medicine-ball-exercises-for-legs/ | C42: 9. Forward Lunge with Twist | D42: Image 9 on page | E42: forward-lunge-with-twist-quads-glutes-obliques-female-1024x683.webp | F42: Medicine Ball Forward Lunge with Twist | G42: Replace image with GIF | I42: Yes | J42: =IF($I42="Yes",IFERROR(INDEX('Buy List'!$A$2:$A$91,MATCH($F42,'Buy List'!$C$2:$C$91,0)),"-"),"-") -> 2 | K42: WRONG | L42: Panel 3 is labelled 'rotate toward lead leg', but the ball turns away from the front leg.
A43: 42 | B43: https://exercisemenu.com/10-medicine-ball-exercises-for-legs/ | C43: 10. Medicine Ball Hip Thrust | D43: Image 10 on page | E43: medicine-ball-hip-thrust-glutes-hamstrings-female-1024x683.webp | F43: Medicine Ball Hip Thrust | G43: Add GIF beside image | H43: Keep the branded infographic (cues, sets, do/don't) and add the GIF above it | I43: Yes | J43: =IF($I43="Yes",IFERROR(INDEX('Buy List'!$A$2:$A$91,MATCH($F43,'Buy List'!$C$2:$C$91,0)),"-"),"-") -> 46 | K43: OK | L43: Good.
A44: 43 | B44: https://exercisemenu.com/10-medicine-ball-chest-exercises/ | C44: 1. Medicine Ball Incline Push-Up | D44: Image 1 on page | E44: medicine-ball-chest-incline-push-up-1-1024x512.webp | F44: Medicine Ball Incline Push-Up | G44: Add GIF beside image | H44: Keep the branded infographic (cues, sets, do/don't) and add the GIF above it | I44: Yes | J44: =IF($I44="Yes",IFERROR(INDEX('Buy List'!$A$2:$A$91,MATCH($F44,'Buy List'!$C$2:$C$91,0)),"-"),"-") -> 28 | K44: OK | L44: Clear.
...

Sheet Plan Pages (links)
A1: Workout plan page | B1: Exercises named in its tables | C1: What to do
A2: https://exercisemenu.com/7-day-at-home-workout-plan-to-build-muscle/ | B2: Dumbbell Bench Press, Incline Dumbbell Press, Dumbbell Shoulder Press, Lateral Raise, Triceps Extension, Single-Arm Dumbbell Row, Band Pulldown, Band Face Pull, Dumbbell Curl, Hammer Curl, Goblet Squat, Dumbbell Romanian Deadlift, Walking Lunge, Standing Calf Raise, Bulgarian Split Squat, Hip Thrust, Plank | C2: No image to replace. Link each exercise name to its exercise page once that page is live.
A3: https://exercisemenu.com/3-week-beginner-fat-loss-workout-plan-for-women/ | B3: Dumbbell or Band Chest Press, Single-Arm Row, Dumbbell Shoulder Press, Biceps Curl, Triceps Kickback, Goblet Squat, Glute Bridge, Reverse Lunge, Standing Calf Raise, Squat to Press, Bent-Over Row, Plank, Bicycle Crunch | C3: No image to replace. Link each exercise name to its exercise page once that page is live.
A4: https://exercisemenu.com/push-pull-legs-split/ | B4: Barbell Bench Press, Incline Dumbbell Press, Overhead Press, Lateral Raise, Triceps Pushdown, Barbell Row, Lat Pulldown, Seated Cable Row, Face Pull, EZ-Bar Curl, Back Squat, Romanian Deadlift, Leg Press, Hip Thrust, Standing Calf Raise | C4: No image to replace. Link each exercise name to its exercise page once that page is live.
A5: https://exercisemenu.com/bowling-workout-routine/ | B5: Arm Circles, Walking Lunges, Front Plank, Side Plank, Pallof Press, Dead Bug, Rotational Medicine Ball Slam, Goblet Squat, Split Squat, Single-Leg Romanian Deadlift, Lateral Band Walk, Calf Raises, Band Pull-Apart, Face Pull, Dumbbell Row, External Rotation, Wrist Curls, Reverse Wrist Curls, Farmer's Walk | C5: No image to replace. Link each exercise name to its exercise page once that page is live.
A6: https://exercisemenu.com/how-many-reps-and-sets-for-muscle-growth/ | B6: Barbell Bench Press, Barbell Row, Overhead Press, Weighted Pull-Up, Incline Dumbbell Curl, Overhead Triceps Extension, Lateral Raise, Barbell Squat, Romanian Deadlift, Leg Press, Seated Leg Curl, Leg Extension, Standing Calf Raise | C6: No image to replace. Link each exercise name to its exercise page once that page is live.
A7: https://exercisemenu.com/how-many-reps-and-sets-for-muscular-endurance/ | B7: Push-Up, Bodyweight Squat, Walking Lunge, Plank, Leg Raise, Calf Raise, Dumbbell Chest Press, Dumbbell Row, Dumbbell Overhead Press, Cable Face Pull, Wall Sit, Isometric Lunge Hold, Dead Hang | C7: No image to replace. Link each exercise name to its exercise page once that page is live.
A8: https://exercisemenu.com/reps-and-sets-for-couples/ | B8: Goblet Squat, Dumbbell Bench Press, Dumbbell Row, Romanian Deadlift, Plank | C8: No image to replace. Link each exercise name to its exercise page once that page is live.
A9: https://exercisemenu.com/how-to-structure-a-30-minute-workout/ | B9: Bodyweight or Goblet Squat, Push-Up Variation, Single-Leg or Band Hip Hinge | C9: No image to replace. Link each exercise name to its exercise page once that page is live.
